<?xml version="1.0" encoding="utf-8"?>
<!-- This URDF was automatically created by SolidWorks to URDF Exporter! Originally created by Stephen Brawner (brawner@gmail.com) 
     Commit Version: 1.6.0-4-g7f85cfe  Build Version: 1.6.7995.38578
     For more information, please see http://wiki.ros.org/sw_urdf_exporter -->
<robot
  name="simple_arm">
  <link
    name="base_link">
    <inertial>
      <origin
        xyz="0.0018522 0.05694 -9.801E-06"
        rpy="0 0 0" />
      <mass
        value="0.7714" />
      <inertia
        ixx="0.0060829"
        ixy="1.3941E-08"
        ixz="-2.005E-08"
        iyy="0.0027165"
        iyz="-2.9234E-07"
        izz="0.0033769" />
    </inertial>
    <visual>
      <origin
        xyz="0 0 0"
        rpy="0 0 0" />
      <geometry>
        <mesh
          filename="package://simple_arm/meshes/base_link.STL" />
      </geometry>
      <material
        name="">
        <color
          rgba="1 1 1 1" />
      </material>
    </visual>
    <collision>
      <origin
        xyz="0 0 0"
        rpy="0 0 0" />
      <geometry>
        <mesh
          filename="package://simple_arm/meshes/base_link.STL" />
      </geometry>
    </collision>
  </link>
  <link
    name="link_1">
    <inertial>
      <origin
        xyz="0.025622 -2.3462E-05 -0.0065948"
        rpy="0 0 0" />
      <mass
        value="0.99839" />
      <inertia
        ixx="0.00053512"
        ixy="1.4208E-07"
        ixz="1.3214E-07"
        iyy="0.00040041"
        iyz="1.5668E-07"
        izz="0.0005444" />
    </inertial>
    <visual>
      <origin
        xyz="0 0 0"
        rpy="0 0 0" />
      <geometry>
        <mesh
          filename="package://simple_arm/meshes/link_1.STL" />
      </geometry>
      <material
        name="">
        <color
          rgba="1 1 1 1" />
      </material>
    </visual>
    <collision>
      <origin
        xyz="0 0 0"
        rpy="0 0 0" />
      <geometry>
        <mesh
          filename="package://simple_arm/meshes/link_1.STL" />
      </geometry>
    </collision>
  </link>
  <joint
    name="joint_1"
    type="continuous">
    <origin
      xyz="0 0 0"
      rpy="1.5708 0 0" />
    <parent
      link="base_link" />
    <child
      link="link_1" />
    <axis
      xyz="-1 0 0" />
    <limit
      lower="-0.25"
      upper="0.25"
      effort="4"
      velocity="1" />
  </joint>
  <link
    name="link_2">
    <inertial>
      <origin
        xyz="0.18493 -0.030408 6.1802E-05"
        rpy="0 0 0" />
      <mass
        value="0.9625" />
      <inertia
        ixx="0.00022442"
        ixy="-2.5284E-08"
        ixz="-4.6635E-06"
        iyy="0.0025161"
        iyz="3.0635E-08"
        izz="0.0023084" />
    </inertial>
    <visual>
      <origin
        xyz="0 0 0"
        rpy="0 0 0" />
      <geometry>
        <mesh
          filename="package://simple_arm/meshes/link_2.STL" />
      </geometry>
      <material
        name="">
        <color
          rgba="0.92941 0.92941 0.92941 1" />
      </material>
    </visual>
    <collision>
      <origin
        xyz="0 0 0"
        rpy="0 0 0" />
      <geometry>
        <mesh
          filename="package://simple_arm/meshes/link_2.STL" />
      </geometry>
    </collision>
  </link>
  <joint
    name="joint_2"
    type="revolute">
    <origin
      xyz="0.065 0 -0.01475"
      rpy="1.5708 0 -0.0039059" />
    <parent
      link="link_1" />
    <child
      link="link_2" />
    <axis
      xyz="0 1 0" />
    <limit
      lower="-0.25"
      upper="0.25"
      effort="30"
      velocity="1" />
  </joint>
  <link
    name="link_3">
    <inertial>
      <origin
        xyz="0.032229 5.2124E-05 0.019389"
        rpy="0 0 0" />
      <mass
        value="0.45086" />
      <inertia
        ixx="6.2493E-05"
        ixy="-2.4382E-08"
        ixz="-1.3726E-09"
        iyy="7.3391E-05"
        iyz="-6.9733E-08"
        izz="9.4499E-05" />
    </inertial>
    <visual>
      <origin
        xyz="0 0 0"
        rpy="0 0 0" />
      <geometry>
        <mesh
          filename="package://simple_arm/meshes/link_3.STL" />
      </geometry>
      <material
        name="">
        <color
          rgba="1 1 1 1" />
      </material>
    </visual>
    <collision>
      <origin
        xyz="0 0 0"
        rpy="0 0 0" />
      <geometry>
        <mesh
          filename="package://simple_arm/meshes/link_3.STL" />
      </geometry>
    </collision>
  </link>
  <joint
    name="joint_3"
    type="continuous">
    <origin
      xyz="0.26 0 0"
      rpy="-1.5708 0.017313 0" />
    <parent
      link="link_2" />
    <child
      link="link_3" />
    <axis
      xyz="0 0 1" />
    <limit
      effort="25"
      velocity="1" />
  </joint>
  <link
    name="link_4">
    <inertial>
      <origin
        xyz="7.3701E-05 -0.032859 0.0075455"
        rpy="0 0 0" />
      <mass
        value="0.40331" />
      <inertia
        ixx="2.3283E-05"
        ixy="2.9214E-07"
        ixz="2.0291E-08"
        iyy="2.5468E-05"
        iyz="1.3587E-08"
        izz="4.0138E-05" />
    </inertial>
    <visual>
      <origin
        xyz="0 0 0"
        rpy="0 0 0" />
      <geometry>
        <mesh
          filename="package://simple_arm/meshes/link_4.STL" />
      </geometry>
      <material
        name="">
        <color
          rgba="1 1 1 1" />
      </material>
    </visual>
    <collision>
      <origin
        xyz="0 0 0"
        rpy="0 0 0" />
      <geometry>
        <mesh
          filename="package://simple_arm/meshes/link_4.STL" />
      </geometry>
    </collision>
  </link>
  <joint
    name="joint_4"
    type="continuous">
    <origin
      xyz="0.061056 0 0.048"
      rpy="-3.1416 -0.28394 -1.5708" />
    <parent
      link="link_3" />
    <child
      link="link_4" />
    <axis
      xyz="0 1 0" />
    <limit
      effort="5"
      velocity="1" />
  </joint>
  <link
    name="link_5">
    <inertial>
      <origin
        xyz="7.3486E-05 -0.044659 -0.01363"
        rpy="0 0 0" />
      <mass
        value="0.40472" />
      <inertia
        ixx="3.4621E-05"
        ixy="1.3941E-08"
        ixz="2.9235E-07"
        iyy="4.4985E-05"
        iyz="2.005E-08"
        izz="4.4079E-05" />
    </inertial>
    <visual>
      <origin
        xyz="0 0 0"
        rpy="0 0 0" />
      <geometry>
        <mesh
          filename="package://simple_arm/meshes/link_5.STL" />
      </geometry>
      <material
        name="">
        <color
          rgba="0.92941 0.92941 0.92941 1" />
      </material>
    </visual>
    <collision>
      <origin
        xyz="0 0 0"
        rpy="0 0 0" />
      <geometry>
        <mesh
          filename="package://simple_arm/meshes/link_5.STL" />
      </geometry>
    </collision>
  </link>
  <joint
    name="joint_5"
    type="revolute">
    <origin
      xyz="0 -0.05 0"
      rpy="0 0 -0.046508" />
    <parent
      link="link_4" />
    <child
      link="link_5" />
    <axis
      xyz="0 0 1" />
    <limit
      lower="-0.25"
      upper="0.25"
      effort="5"
      velocity="1" />
  </joint>
  <link
    name="link_6">
    <inertial>
      <origin
        xyz="-0.27067 0.1245 0.033038"
        rpy="0 0 0" />
      <mass
        value="0.8765" />
      <inertia
        ixx="0.048624"
        ixy="-3.2745E-10"
        ixz="5.9253E-10"
        iyy="0.048591"
        iyz="-1.6566E-11"
        izz="0.048502" />
    </inertial>
    <visual>
      <origin
        xyz="0 0 0"
        rpy="0 0 0" />
      <geometry>
        <mesh
          filename="package://simple_arm/meshes/link_6.STL" />
      </geometry>
      <material
        name="">
        <color
          rgba="1 1 1 1" />
      </material>
    </visual>
    <collision>
      <origin
        xyz="0 0 0"
        rpy="0 0 0" />
      <geometry>
        <mesh
          filename="package://simple_arm/meshes/link_6.STL" />
      </geometry>
    </collision>
  </link>
  <joint
    name="joint_6"
    type="continuous">
    <origin
      xyz="4.391E-05 -0.00094347 -0.12018"
      rpy="1.309 0 1.5708" />
    <parent
      link="link_5" />
    <child
      link="link_6" />
    <axis
      xyz="0 0.96593 0.25882" />
    <limit
      effort="5"
      velocity="1" />
  </joint>
</robot>