<?xml version="1.0" encoding="utf-8"?>
<robot name="simplebb">
  <link name="base_footprint">
      <visual>
        <geometry>
          <sphere radius="0.0001" />
        </geometry>
      </visual>
    </link>
  <link
    name="base_link">
    <inertial>
      <origin
        xyz="0 -5.5511E-17 -0.026187"
        rpy="0 0 0" />
      <mass
        value="24.1499" />
      <inertia
        ixx="19.541"
        ixy="0"
        ixz="0"
        iyy="2.4546"
        iyz="0"
        izz="4.1766" />
    </inertial>
    <visual>
      <origin
        xyz="0 0 0"
        rpy="0 0 0" />
      <geometry>
        <mesh
          filename="package://simplebb/meshes/base_link.STL" />
      </geometry>
      <material
        name="">
        <color
          rgba="1 1 1 1" />
      </material>
    </visual>
    <collision>
      <origin
        xyz="0 0 0"
        rpy="0 0 0" />
      <geometry>
        <mesh
          filename="package://simplebb/meshes/base_link.STL" />
      </geometry>
    </collision>
  </link>
  <joint name="base_link2base_footprint" type="fixed">
      <parent link="base_footprint" />
      <child link="base_link" />
      <origin xyz="0 0 0.14842" />
    </joint>
  <link name="f_l_l">
    <inertial>
      <origin xyz="1.305E-06 0.014423 4.6233E-06" rpy="0 0 0" />
      <mass value="0.21836" />
      <inertia ixx="0.00010444" ixy="-9.9501E-08" ixz="-1.3183E-07" iyy="0.00018522" iyz="2.8085E-08" izz="0.00010401" />
    </inertial>
    <visual>
      <origin xyz="0 0 0" rpy="0 0 0" />
      <geometry>
        <mesh filename="package://simplebb/meshes/f_l_l.STL" />
      </geometry>
      <material name="">
        <color rgba="1 1 1 1" />
      </material>
    </visual>
    <collision>
      <origin xyz="0 0 0" rpy="0 0 0" />
      <geometry>
        <mesh filename="package://simplebb/meshes/f_l_l.STL" />
      </geometry>
    </collision>
  </link>
  <joint name="f_l_j" type="continuous">
    <origin xyz="0.1838 0.1899 -0.14842" rpy="0 0 0" />
    <parent link="base_link" />
    <child link="f_l_l" />
    <axis xyz="0 -1 0" />
  </joint>
  <link name="f_r_l">
    <inertial>
      <origin xyz="1.3052E-06 -0.014178 4.6234E-06" rpy="0 0 0" />
      <mass value="0.21836" />
      <inertia ixx="0.00010444" ixy="-9.95E-08" ixz="-1.3184E-07" iyy="0.00018522" iyz="2.8085E-08" izz="0.00010401" />
    </inertial>
    <visual>
      <origin xyz="0 0 0" rpy="0 0 0" />
      <geometry>
        <mesh filename="package://simplebb/meshes/f_r_l.STL" />
      </geometry>
      <material name="">
        <color rgba="1 1 1 1" />
      </material>
    </visual>
    <collision>
      <origin xyz="0 0 0" rpy="0 0 0" />
      <geometry>
        <mesh filename="package://simplebb/meshes/f_r_l.STL" />
      </geometry>
    </collision>
  </link>
  <joint name="f_r_j" type="continuous">
    <origin xyz="0.1838 -0.1899 -0.14842" rpy="0 0 0" />
    <parent link="base_link" />
    <child link="f_r_l" />
    <axis
      xyz="0 1 0" />
  </joint>
  <link name="b_l_l">
    <inertial>
      <origin xyz="1.3052E-06 0.013623 4.6233E-06" rpy="0 0 0" />
      <mass value="0.21836" />
      <inertia ixx="0.00010444" ixy="-9.95E-08" ixz="-1.3183E-07" iyy="0.00018522" iyz="2.8085E-08" izz="0.00010401" />
    </inertial>
    <visual>
      <origin xyz="0 0 0" rpy="0 0 0" />
      <geometry>
        <mesh filename="package://simplebb/meshes/b_l_l.STL" />
      </geometry>
      <material name="">
        <color rgba="1 1 1 1" />
      </material>
    </visual>
    <collision>
      <origin xyz="0 0 0" rpy="0 0 0" />
      <geometry>
        <mesh filename="package://simplebb/meshes/b_l_l.STL" />
      </geometry>
    </collision>
  </link>
  <joint name="b_l_j" type="continuous">
    <origin xyz="-0.1838 0.1899 -0.14842" rpy="0 0 0" />
    <parent link="base_link" />
    <child link="b_l_l" />
    <axis xyz="0 -1 0" />
  </joint>
  <link name="b_r_l">
    <inertial>
      <origin xyz="1.3052E-06 -0.013623 4.6233E-06" rpy="0 0 0" />
      <mass value="0.21836" />
      <inertia ixx="0.00010444" ixy="-9.95E-08" ixz="-1.3183E-07" iyy="0.00018522" iyz="2.8085E-08" izz="0.00010401" />
    </inertial>
    <visual>
      <origin xyz="0 0 0" rpy="0 0 0" />
      <geometry>
        <mesh filename="package://simplebb/meshes/b_r_l.STL" />
      </geometry>
      <material name="">
        <color rgba="1 1 1 1" />
      </material>
    </visual>
    <collision>
      <origin xyz="0 0 0" rpy="0 0 0" />
      <geometry>
        <mesh filename="package://simplebb/meshes/b_r_l.STL" />
      </geometry>
    </collision>
  </link>
  <joint name="b_r_j" type="continuous">
    <origin xyz="-0.1838 -0.1899 -0.14842" rpy="0 0 0" />
    <parent link="base_link" />
    <child link="b_r_l" />
    <axis xyz="0 1 0" />
  </joint>

</robot>